<sdf version='1.6'>
  <world name='default'>
    <light name='sun' type='directional'>
      <cast_shadows>1</cast_shadows>
      <pose frame=''>0 0 10 0 -0 0</pose>
      <diffuse>0.8 0.8 0.8 1</diffuse>
      <specular>0.1 0.1 0.1 1</specular>
      <attenuation>
        <range>1000</range>
        <constant>0.9</constant>
        <linear>0.01</linear>
        <quadratic>0.001</quadratic>
      </attenuation>
      <direction>-0.5 0.5 -1</direction>
    </light>
    <model name='ground_plane'>
      <static>1</static>
      <link name='link'>
        <collision name='collision'>
          <geometry>
            <plane>
              <normal>0 0 1</normal>
              <size>100 100</size>
            </plane>
          </geometry>
          <surface>
            <friction>
              <bullet/>
              <ode/>
            </friction>
            <contact>
              <bullet>
                <split_impulse>1</split_impulse>
                <split_impulse_penetration_threshold>-0.05</split_impulse_penetration_threshold>
                <soft_cfm>0</soft_cfm>
                <soft_erp>0.05</soft_erp>
                <kp>1e+16</kp>
                <kd>100</kd>
              </bullet>
            </contact>
          </surface>
          <max_contacts>20</max_contacts>
        </collision>
        <visual name='visual'>
          <cast_shadows>0</cast_shadows>
          <geometry>
            <plane>
              <normal>0 0 1</normal>
              <size>100 100</size>
            </plane>
          </geometry>
          <material>
            <script>
              <uri>file://media/materials/scripts/gazebo.material</uri>
              <name>Gazebo/Grey</name>
            </script>
          </material>
        </visual>
        <self_collide>0</self_collide>
        <gravity>1</gravity>
      </link>
    </model>
    <gravity>0 0 -9.8</gravity>
    <magnetic_field>6e-06 2.3e-05 -4.2e-05</magnetic_field>
    <atmosphere type='adiabatic'/>
    <physics name='default_physics' default='1' type='bullet'>
      <max_step_size>0.001</max_step_size>
      <real_time_factor>1</real_time_factor>
      <real_time_update_rate>1000</real_time_update_rate>
    </physics>
    <scene>
      <ambient>0.4 0.4 0.4 1</ambient>
      <background>0.7 0.7 0.7 1</background>
      <shadows>1</shadows>
    </scene>
    <spherical_coordinates>
      <surface_model>EARTH_WGS84</surface_model>
      <latitude_deg>0</latitude_deg>
      <longitude_deg>0</longitude_deg>
      <elevation>0</elevation>
      <heading_deg>0</heading_deg>
    </spherical_coordinates>
    <state world_name='default'>
      <sim_time>9 506000000</sim_time>
      <real_time>0 0</real_time>
      <wall_time>1515163103 484377888</wall_time>
      <iterations>0</iterations>
      <model name='ground_plane'>
        <pose frame=''>0 0 0 0 -0 0</pose>
        <scale>1 1 1</scale>
        <link name='link'>
          <pose frame=''>0 0 0 0 -0 0</pose>
          <velocity>0 0 0 0 -0 0</velocity>
          <acceleration>0 0 0 0 -0 0</acceleration>
          <wrench>0 0 0 0 -0 0</wrench>
        </link>
      </model>
      <model name='slider_gazebo'>
        <pose frame=''>0 0 0 0 -0 0</pose>
        <scale>1 1 1</scale>
        <link name='base_link'>
          <pose frame=''>0 0 0 0 -0 0</pose>
          <velocity>0 0 0 0 -0 0</velocity>
          <acceleration>0 0 0 0 -0 0</acceleration>
          <wrench>0 0 0 0 -0 0</wrench>
        </link>
        <link name='left_ankle'>
          <pose frame=''>0 -0.157822 0.055537 0 -0 0</pose>
          <velocity>0 0 0 0 -0 0</velocity>
          <acceleration>0 0 0 0 -0 0</acceleration>
          <wrench>0 0 0 0 -0 0</wrench>
        </link>
        <link name='left_base'>
          <pose frame=''>0 -0.2 0.82 0 -0 0</pose>
          <velocity>0 0 0 0 -0 0</velocity>
          <acceleration>0 0 0 0 -0 0</acceleration>
          <wrench>0 0 0 0 -0 0</wrench>
        </link>
        <link name='left_foot'>
          <pose frame=''>0 -0.157822 0.035537 0 -0 0</pose>
          <velocity>0 0 0 0 -0 0</velocity>
          <acceleration>0 0 0 0 -0 0</acceleration>
          <wrench>0 0 0 0 -0 0</wrench>
        </link>
        <link name='left_leg'>
          <pose frame=''>0 -0.25 0.82 0.12 -0 0</pose>
          <velocity>0 0 0 0 -0 0</velocity>
          <acceleration>0 0 0 0 -0 0</acceleration>
          <wrench>0 0 0 0 -0 0</wrench>
        </link>
        <link name='left_pad1'>
          <pose frame=''>-0.08 -0.127822 0.025537 0 -0 0</pose>
          <velocity>0 0 0 0 -0 0</velocity>
          <acceleration>0 0 0 0 -0 0</acceleration>
          <wrench>0 0 0 0 -0 0</wrench>
        </link>
        <link name='left_pad2'>
          <pose frame=''>-0.08 -0.187822 0.025537 0 -0 0</pose>
          <velocity>0 0 0 0 -0 0</velocity>
          <acceleration>0 0 0 0 -0 0</acceleration>
          <wrench>0 0 0 0 -0 0</wrench>
        </link>
        <link name='left_pad3'>
          <pose frame=''>0.08 -0.187822 0.025537 0 -0 0</pose>
          <velocity>0 0 0 0 -0 0</velocity>
          <acceleration>0 0 0 0 -0 0</acceleration>
          <wrench>0 0 0 0 -0 0</wrench>
        </link>
        <link name='left_pad4'>
          <pose frame=''>0.08 -0.127822 0.025537 0 -0 0</pose>
          <velocity>0 0 0 0 -0 0</velocity>
          <acceleration>0 0 0 0 -0 0</acceleration>
          <wrench>0 0 0 0 -0 0</wrench>
        </link>
        <link name='right_ankle'>
          <pose frame=''>0 0.157822 0.055537 0 -0 0</pose>
          <velocity>0 0 0 0 -0 0</velocity>
          <acceleration>0 0 0 0 -0 0</acceleration>
          <wrench>0 0 0 0 -0 0</wrench>
        </link>
        <link name='right_base'>
          <pose frame=''>0 0.2 0.82 0 -0 0</pose>
          <velocity>0 0 0 0 -0 0</velocity>
          <acceleration>0 0 0 0 -0 0</acceleration>
          <wrench>0 0 0 0 -0 0</wrench>
        </link>
        <link name='right_foot'>
          <pose frame=''>0 0.157822 0.035537 0 -0 0</pose>
          <velocity>0 0 0 0 -0 0</velocity>
          <acceleration>0 0 0 0 -0 0</acceleration>
          <wrench>0 0 0 0 -0 0</wrench>
        </link>
        <link name='right_leg'>
          <pose frame=''>0 0.25 0.82 -0.12 0 0</pose>
          <velocity>0 0 0 0 -0 0</velocity>
          <acceleration>0 0 0 0 -0 0</acceleration>
          <wrench>0 0 0 0 -0 0</wrench>
        </link>
        <link name='right_pad1'>
          <pose frame=''>-0.08 0.187822 0.025537 0 -0 0</pose>
          <velocity>0 0 0 0 -0 0</velocity>
          <acceleration>0 0 0 0 -0 0</acceleration>
          <wrench>0 0 0 0 -0 0</wrench>
        </link>
        <link name='right_pad2'>
          <pose frame=''>-0.08 0.127822 0.025537 0 -0 0</pose>
          <velocity>0 0 0 0 -0 0</velocity>
          <acceleration>0 0 0 0 -0 0</acceleration>
          <wrench>0 0 0 0 -0 0</wrench>
        </link>
        <link name='right_pad3'>
          <pose frame=''>0.08 0.127822 0.025537 0 -0 0</pose>
          <velocity>0 0 0 0 -0 0</velocity>
          <acceleration>0 0 0 0 -0 0</acceleration>
          <wrench>0 0 0 0 -0 0</wrench>
        </link>
        <link name='right_pad4'>
          <pose frame=''>0.08 0.187822 0.025537 0 -0 0</pose>
          <velocity>0 0 0 0 -0 0</velocity>
          <acceleration>0 0 0 0 -0 0</acceleration>
          <wrench>0 0 0 0 -0 0</wrench>
        </link>
      </model>
      <light name='sun'>
        <pose frame=''>0 0 10 0 -0 0</pose>
      </light>
    </state>
    <gui fullscreen='0'>
      <camera name='user_camera'>
        <pose frame=''>4.59656 -3.10062 2.14364 0 0.275643 2.35619</pose>
        <view_controller>orbit</view_controller>
        <projection_type>perspective</projection_type>
      </camera>
    </gui>
    <model name='slider_gazebo'>
      <link name='base_link'>
        <pose frame=''>0 0 0 0 -0 0</pose>
        <inertial>
          <pose frame=''>0 0 0.81 0 -0 0</pose>
          <mass>2.5</mass>
          <inertia>
            <ixx>0.18</ixx>
            <ixy>0</ixy>
            <ixz>0</ixz>
            <iyy>0.17</iyy>
            <iyz>0</iyz>
            <izz>0.18</izz>
          </inertia>
        </inertial>
        <collision name='base_link_collision'>
          <pose frame=''>0 0 0.82 0 -0 0</pose>
          <geometry>
            <box>
              <size>0.16 0.4 0.18</size>
            </box>
          </geometry>
          <max_contacts>10</max_contacts>
          <surface>
            <contact/>
            <friction>
              <ode/>
            </friction>
          </surface>
        </collision>
        <visual name='base_link_visual'>
          <pose frame=''>0 0 0.82 0 -0 0</pose>
          <geometry>
            <box>
              <size>0.16 0.4 0.18</size>
            </box>
          </geometry>
        </visual>
        <self_collide>0</self_collide>
      </link>
      <link name='left_base'>
        <pose frame=''>0 -0.2 0.82 0 -0 0</pose>
        <inertial>
          <pose frame=''>0 0 0 0 -0 0</pose>
          <mass>2.12</mass>
          <inertia>
            <ixx>0.8</ixx>
            <ixy>0</ixy>
            <ixz>0</ixz>
            <iyy>0.8</iyy>
            <iyz>0</iyz>
            <izz>0.8</izz>
          </inertia>
        </inertial>
        <collision name='left_base_collision'>
          <pose frame=''>0 0 0 1.57 -0 0</pose>
          <geometry>
            <cylinder>
              <length>0.01</length>
              <radius>0.02</radius>
            </cylinder>
          </geometry>
          <max_contacts>10</max_contacts>
          <surface>
            <contact/>
            <friction>
              <ode/>
            </friction>
          </surface>
        </collision>
        <visual name='left_base_visual'>
          <pose frame=''>0 0 0 1.57 -0 0</pose>
          <geometry>
            <cylinder>
              <length>0.01</length>
              <radius>0.02</radius>
            </cylinder>
          </geometry>
        </visual>
        <self_collide>0</self_collide>
      </link>
      <joint name='left_hip_pitch' type='revolute'>
        <child>left_base</child>
        <parent>base_link</parent>
        <axis>
          <xyz>0 1 0</xyz>
          <limit>
            <lower>-1.5707</lower>
            <upper>1.5707</upper>
            <effort>1000</effort>
            <velocity>1.5</velocity>
          </limit>
          <dynamics>
            <spring_reference>0</spring_reference>
            <spring_stiffness>0</spring_stiffness>
          </dynamics>
          <use_parent_model_frame>1</use_parent_model_frame>
        </axis>
      </joint>
      <link name='left_leg'>
        <pose frame=''>0 -0.25 0.82 0.12 -0 0</pose>
        <inertial>
          <pose frame=''>0 0 -0.27 0 -0 0</pose>
          <mass>1.5</mass>
          <inertia>
            <ixx>0.5</ixx>
            <ixy>0</ixy>
            <ixz>0</ixz>
            <iyy>0.5</iyy>
            <iyz>0</iyz>
            <izz>1.5</izz>
          </inertia>
        </inertial>
        <collision name='left_leg_collision'>
          <pose frame=''>0 0 -0.27 0 -0 0</pose>
          <geometry>
            <box>
              <size>0.1 0.1 0.96</size>
            </box>
          </geometry>
          <max_contacts>10</max_contacts>
          <surface>
            <contact/>
            <friction>
              <ode/>
            </friction>
          </surface>
        </collision>
        <visual name='left_leg_visual'>
          <pose frame=''>0 0 -0.27 0 -0 0</pose>
          <geometry>
            <box>
              <size>0.1 0.1 0.96</size>
            </box>
          </geometry>
        </visual>
        <self_collide>0</self_collide>
      </link>
      <joint name='left_hip_slide' type='prismatic'>
        <child>left_leg</child>
        <parent>left_base</parent>
        <axis>
          <xyz>0 -0.119712 0.992809</xyz>
          <limit>
            <lower>0</lower>
            <upper>0</upper>
            <effort>10000</effort>
            <velocity>1.5</velocity>
          </limit>
          <dynamics>
            <spring_reference>0</spring_reference>
            <spring_stiffness>0</spring_stiffness>
          </dynamics>
          <use_parent_model_frame>1</use_parent_model_frame>
        </axis>
      </joint>
      <link name='left_ankle'>
        <pose frame=''>0 -0.157822 0.055537 0 -0 0</pose>
        <inertial>
          <pose frame=''>0 0 -0 0 -0 0</pose>
          <mass>0.1</mass>
          <inertia>
            <ixx>0.1</ixx>
            <ixy>0</ixy>
            <ixz>0</ixz>
            <iyy>0.1</iyy>
            <iyz>0</iyz>
            <izz>0.1</izz>
          </inertia>
        </inertial>
        <collision name='left_ankle_collision'>
          <pose frame=''>0 0 -0 0 -0 0</pose>
          <geometry>
            <cylinder>
              <length>0.03</length>
              <radius>0.02</radius>
            </cylinder>
          </geometry>
          <max_contacts>10</max_contacts>
          <surface>
            <contact/>
            <friction>
              <ode/>
            </friction>
          </surface>
        </collision>
        <visual name='left_ankle_visual'>
          <pose frame=''>0 0 -0 0 -0 0</pose>
          <geometry>
            <cylinder>
              <length>0.04</length>
              <radius>0.02</radius>
            </cylinder>
          </geometry>
        </visual>
        <self_collide>0</self_collide>
      </link>
      <joint name='left_ankle_pitch' type='revolute'>
        <child>left_ankle</child>
        <parent>left_leg</parent>
        <axis>
          <xyz>0 1 0</xyz>
          <limit>
            <lower>-1</lower>
            <upper>1</upper>
            <effort>1000</effort>
            <velocity>0.5</velocity>
          </limit>
          <dynamics>
            <spring_reference>0</spring_reference>
            <spring_stiffness>0</spring_stiffness>
          </dynamics>
          <use_parent_model_frame>1</use_parent_model_frame>
        </axis>
      </joint>
      <link name='left_foot'>
        <pose frame=''>0 -0.157822 0.035537 0 -0 0</pose>
        <inertial>
          <pose frame=''>0 0 0 0 -0 0</pose>
          <mass>0.336</mass>
          <inertia>
            <ixx>0.2</ixx>
            <ixy>0</ixy>
            <ixz>0</ixz>
            <iyy>0.2</iyy>
            <iyz>0</iyz>
            <izz>0.2</izz>
          </inertia>
        </inertial>
        <collision name='left_foot_collision'>
          <pose frame=''>0 0 0 0 -0 0</pose>
          <geometry>
            <box>
              <size>0.16 0.08 0.01</size>
            </box>
          </geometry>
          <max_contacts>10</max_contacts>
          <surface>
            <contact/>
            <friction>
              <ode/>
            </friction>
          </surface>
        </collision>
        <visual name='left_foot_visual'>
          <pose frame=''>0 0 0 0 -0 0</pose>
          <geometry>
            <box>
              <size>0.2 0.1 0.01</size>
            </box>
          </geometry>
        </visual>
        <self_collide>0</self_collide>
      </link>
      <joint name='left_ankle_roll' type='revolute'>
        <child>left_foot</child>
        <parent>left_ankle</parent>
        <axis>
          <xyz>0 0 1</xyz>
          <limit>
            <lower>-1</lower>
            <upper>1</upper>
            <effort>1000</effort>
            <velocity>0.5</velocity>
          </limit>
          <dynamics>
            <spring_reference>0</spring_reference>
            <spring_stiffness>0</spring_stiffness>
          </dynamics>
          <use_parent_model_frame>1</use_parent_model_frame>
        </axis>
      </joint>
      <link name='left_pad1'>
        <pose frame=''>-0.08 -0.127822 0.025537 0 -0 0</pose>
        <inertial>
          <pose frame=''>0 0 0 0 -0 0</pose>
          <mass>0.001</mass>
          <inertia>
            <ixx>0.01</ixx>
            <ixy>0</ixy>
            <ixz>0</ixz>
            <iyy>0.01</iyy>
            <iyz>0</iyz>
            <izz>0.01</izz>
          </inertia>
        </inertial>
        <collision name='left_pad1_collision'>
          <pose frame=''>0 0 0 0 -0 0</pose>
          <geometry>
            <sphere>
              <radius>0.015</radius>
            </sphere>
          </geometry>
          <max_contacts>10</max_contacts>
          <surface>
            <contact/>
            <friction>
              <ode/>
            </friction>
          </surface>
        </collision>
        <visual name='left_pad1_visual'>
          <pose frame=''>0 0 0 0 -0 0</pose>
          <geometry>
            <sphere>
              <radius>0.015</radius>
            </sphere>
          </geometry>
        </visual>
        <self_collide>0</self_collide>
      </link>
      <joint name='left_foot_pad1' type='revolute'>
        <child>left_pad1</child>
        <parent>left_foot</parent>
        <axis>
          <xyz>1 0 0</xyz>
          <limit>
            <lower>0</lower>
            <upper>0</upper>
            <effort>1000</effort>
            <velocity>0.5</velocity>
          </limit>
          <dynamics>
            <spring_reference>0</spring_reference>
            <spring_stiffness>0</spring_stiffness>
          </dynamics>
          <use_parent_model_frame>1</use_parent_model_frame>
        </axis>
      </joint>
      <link name='left_pad2'>
        <pose frame=''>-0.08 -0.187822 0.025537 0 -0 0</pose>
        <inertial>
          <pose frame=''>0 0 0 0 -0 0</pose>
          <mass>0.001</mass>
          <inertia>
            <ixx>0.01</ixx>
            <ixy>0</ixy>
            <ixz>0</ixz>
            <iyy>0.01</iyy>
            <iyz>0</iyz>
            <izz>0.01</izz>
          </inertia>
        </inertial>
        <collision name='left_pad2_collision'>
          <pose frame=''>0 0 0 0 -0 0</pose>
          <geometry>
            <sphere>
              <radius>0.015</radius>
            </sphere>
          </geometry>
          <max_contacts>10</max_contacts>
          <surface>
            <contact/>
            <friction>
              <ode/>
            </friction>
          </surface>
        </collision>
        <visual name='left_pad2_visual'>
          <pose frame=''>0 0 0 0 -0 0</pose>
          <geometry>
            <sphere>
              <radius>0.015</radius>
            </sphere>
          </geometry>
        </visual>
        <self_collide>0</self_collide>
      </link>
      <joint name='left_foot_pad2' type='revolute'>
        <child>left_pad2</child>
        <parent>left_foot</parent>
        <axis>
          <xyz>1 0 0</xyz>
          <limit>
            <lower>0</lower>
            <upper>0</upper>
            <effort>1000</effort>
            <velocity>0.5</velocity>
          </limit>
          <dynamics>
            <spring_reference>0</spring_reference>
            <spring_stiffness>0</spring_stiffness>
          </dynamics>
          <use_parent_model_frame>1</use_parent_model_frame>
        </axis>
      </joint>
      <link name='left_pad3'>
        <pose frame=''>0.08 -0.187822 0.025537 0 -0 0</pose>
        <inertial>
          <pose frame=''>0 0 0 0 -0 0</pose>
          <mass>0.001</mass>
          <inertia>
            <ixx>0.01</ixx>
            <ixy>0</ixy>
            <ixz>0</ixz>
            <iyy>0.01</iyy>
            <iyz>0</iyz>
            <izz>0.01</izz>
          </inertia>
        </inertial>
        <collision name='left_pad3_collision'>
          <pose frame=''>0 0 0 0 -0 0</pose>
          <geometry>
            <sphere>
              <radius>0.015</radius>
            </sphere>
          </geometry>
          <max_contacts>10</max_contacts>
          <surface>
            <contact/>
            <friction>
              <ode/>
            </friction>
          </surface>
        </collision>
        <visual name='left_pad3_visual'>
          <pose frame=''>0 0 0 0 -0 0</pose>
          <geometry>
            <sphere>
              <radius>0.015</radius>
            </sphere>
          </geometry>
        </visual>
        <self_collide>0</self_collide>
      </link>
      <joint name='left_foot_pad3' type='revolute'>
        <child>left_pad3</child>
        <parent>left_foot</parent>
        <axis>
          <xyz>1 0 0</xyz>
          <limit>
            <lower>0</lower>
            <upper>0</upper>
            <effort>1000</effort>
            <velocity>0.5</velocity>
          </limit>
          <dynamics>
            <spring_reference>0</spring_reference>
            <spring_stiffness>0</spring_stiffness>
          </dynamics>
          <use_parent_model_frame>1</use_parent_model_frame>
        </axis>
      </joint>
      <link name='left_pad4'>
        <pose frame=''>0.08 -0.127822 0.025537 0 -0 0</pose>
        <inertial>
          <pose frame=''>0 0 0 0 -0 0</pose>
          <mass>0.001</mass>
          <inertia>
            <ixx>0.01</ixx>
            <ixy>0</ixy>
            <ixz>0</ixz>
            <iyy>0.01</iyy>
            <iyz>0</iyz>
            <izz>0.01</izz>
          </inertia>
        </inertial>
        <collision name='left_pad4_collision'>
          <pose frame=''>0 0 0 0 -0 0</pose>
          <geometry>
            <sphere>
              <radius>0.015</radius>
            </sphere>
          </geometry>
          <max_contacts>10</max_contacts>
          <surface>
            <contact/>
            <friction>
              <ode/>
            </friction>
          </surface>
        </collision>
        <visual name='left_pad4_visual'>
          <pose frame=''>0 0 0 0 -0 0</pose>
          <geometry>
            <sphere>
              <radius>0.015</radius>
            </sphere>
          </geometry>
        </visual>
        <self_collide>0</self_collide>
      </link>
      <joint name='left_foot_pad4' type='revolute'>
        <child>left_pad4</child>
        <parent>left_foot</parent>
        <axis>
          <xyz>1 0 0</xyz>
          <limit>
            <lower>0</lower>
            <upper>0</upper>
            <effort>1000</effort>
            <velocity>0.5</velocity>
          </limit>
          <dynamics>
            <spring_reference>0</spring_reference>
            <spring_stiffness>0</spring_stiffness>
          </dynamics>
          <use_parent_model_frame>1</use_parent_model_frame>
        </axis>
      </joint>
      <link name='right_base'>
        <pose frame=''>0 0.2 0.82 0 -0 0</pose>
        <inertial>
          <pose frame=''>0 0 0 0 -0 0</pose>
          <mass>2.12</mass>
          <inertia>
            <ixx>0.8</ixx>
            <ixy>0</ixy>
            <ixz>0</ixz>
            <iyy>0.8</iyy>
            <iyz>0</iyz>
            <izz>0.8</izz>
          </inertia>
        </inertial>
        <collision name='right_base_collision'>
          <pose frame=''>0 0 0 1.57 -0 0</pose>
          <geometry>
            <cylinder>
              <length>0.01</length>
              <radius>0.02</radius>
            </cylinder>
          </geometry>
          <max_contacts>10</max_contacts>
          <surface>
            <contact/>
            <friction>
              <ode/>
            </friction>
          </surface>
        </collision>
        <visual name='right_base_visual'>
          <pose frame=''>0 0 0 1.57 -0 0</pose>
          <geometry>
            <cylinder>
              <length>0.01</length>
              <radius>0.02</radius>
            </cylinder>
          </geometry>
        </visual>
        <self_collide>0</self_collide>
      </link>
      <joint name='right_hip_pitch' type='revolute'>
        <child>right_base</child>
        <parent>base_link</parent>
        <axis>
          <xyz>0 1 0</xyz>
          <limit>
            <lower>-1.5707</lower>
            <upper>1.5707</upper>
            <effort>1000</effort>
            <velocity>0.5</velocity>
          </limit>
          <dynamics>
            <spring_reference>0</spring_reference>
            <spring_stiffness>0</spring_stiffness>
          </dynamics>
          <use_parent_model_frame>1</use_parent_model_frame>
        </axis>
      </joint>
      <link name='right_leg'>
        <pose frame=''>0 0.25 0.82 -0.12 0 0</pose>
        <inertial>
          <pose frame=''>0 0 -0.27 0 -0 0</pose>
          <mass>1.5</mass>
          <inertia>
            <ixx>0.5</ixx>
            <ixy>0</ixy>
            <ixz>0</ixz>
            <iyy>0.5</iyy>
            <iyz>0</iyz>
            <izz>1.5</izz>
          </inertia>
        </inertial>
        <collision name='right_leg_collision'>
          <pose frame=''>0 0 -0.27 0 -0 0</pose>
          <geometry>
            <box>
              <size>0.1 0.1 0.96</size>
            </box>
          </geometry>
          <max_contacts>10</max_contacts>
          <surface>
            <contact/>
            <friction>
              <ode/>
            </friction>
          </surface>
        </collision>
        <visual name='right_leg_visual'>
          <pose frame=''>0 0 -0.27 0 -0 0</pose>
          <geometry>
            <box>
              <size>0.1 0.1 0.96</size>
            </box>
          </geometry>
        </visual>
        <self_collide>0</self_collide>
      </link>
      <joint name='right_hip_slide' type='prismatic'>
        <child>right_leg</child>
        <parent>right_base</parent>
        <axis>
          <xyz>0 0.119712 0.992809</xyz>
          <limit>
            <lower>-0</lower>
            <upper>0</upper>
            <effort>10000</effort>
            <velocity>1.5</velocity>
          </limit>
          <dynamics>
            <spring_reference>0</spring_reference>
            <spring_stiffness>0</spring_stiffness>
          </dynamics>
          <use_parent_model_frame>1</use_parent_model_frame>
        </axis>
      </joint>
      <link name='right_ankle'>
        <pose frame=''>0 0.157822 0.055537 0 -0 0</pose>
        <inertial>
          <pose frame=''>0 0 0 0 -0 0</pose>
          <mass>0.1</mass>
          <inertia>
            <ixx>0.1</ixx>
            <ixy>0</ixy>
            <ixz>0</ixz>
            <iyy>0.1</iyy>
            <iyz>0</iyz>
            <izz>0.1</izz>
          </inertia>
        </inertial>
        <collision name='right_ankle_collision'>
          <pose frame=''>0 0 0 0 -0 0</pose>
          <geometry>
            <cylinder>
              <length>0.03</length>
              <radius>0.02</radius>
            </cylinder>
          </geometry>
          <max_contacts>10</max_contacts>
          <surface>
            <contact/>
            <friction>
              <ode/>
            </friction>
          </surface>
        </collision>
        <visual name='right_ankle_visual'>
          <pose frame=''>0 0 0 0 -0 0</pose>
          <geometry>
            <cylinder>
              <length>0.04</length>
              <radius>0.02</radius>
            </cylinder>
          </geometry>
        </visual>
        <self_collide>0</self_collide>
      </link>
      <joint name='right_ankle_pitch' type='revolute'>
        <child>right_ankle</child>
        <parent>right_leg</parent>
        <axis>
          <xyz>0 1 0</xyz>
          <limit>
            <lower>-0.6</lower>
            <upper>0.6</upper>
            <effort>1000</effort>
            <velocity>0.5</velocity>
          </limit>
          <dynamics>
            <spring_reference>0</spring_reference>
            <spring_stiffness>0</spring_stiffness>
          </dynamics>
          <use_parent_model_frame>1</use_parent_model_frame>
        </axis>
      </joint>
      <link name='right_foot'>
        <pose frame=''>0 0.157822 0.035537 0 -0 0</pose>
        <inertial>
          <pose frame=''>0 0 0 0 -0 0</pose>
          <mass>0.336</mass>
          <inertia>
            <ixx>0.2</ixx>
            <ixy>0</ixy>
            <ixz>0</ixz>
            <iyy>0.2</iyy>
            <iyz>0</iyz>
            <izz>0.2</izz>
          </inertia>
        </inertial>
        <collision name='right_foot_collision'>
          <pose frame=''>0 0 0 0 -0 0</pose>
          <geometry>
            <box>
              <size>0.16 0.08 0.01</size>
            </box>
          </geometry>
          <max_contacts>10</max_contacts>
          <surface>
            <contact/>
            <friction>
              <ode/>
            </friction>
          </surface>
        </collision>
        <visual name='right_foot_visual'>
          <pose frame=''>0 0 0 0 -0 0</pose>
          <geometry>
            <box>
              <size>0.2 0.1 0.01</size>
            </box>
          </geometry>
        </visual>
        <self_collide>0</self_collide>
      </link>
      <joint name='right_ankle_roll' type='revolute'>
        <child>right_foot</child>
        <parent>right_ankle</parent>
        <axis>
          <xyz>0 0 1</xyz>
          <limit>
            <lower>-0.6</lower>
            <upper>0.6</upper>
            <effort>1000</effort>
            <velocity>0.5</velocity>
          </limit>
          <dynamics>
            <spring_reference>0</spring_reference>
            <spring_stiffness>0</spring_stiffness>
          </dynamics>
          <use_parent_model_frame>1</use_parent_model_frame>
        </axis>
      </joint>
      <link name='right_pad1'>
        <pose frame=''>-0.08 0.187822 0.025537 0 -0 0</pose>
        <inertial>
          <pose frame=''>0 0 0 0 -0 0</pose>
          <mass>0.001</mass>
          <inertia>
            <ixx>0.01</ixx>
            <ixy>0</ixy>
            <ixz>0</ixz>
            <iyy>0.01</iyy>
            <iyz>0</iyz>
            <izz>0.01</izz>
          </inertia>
        </inertial>
        <collision name='right_pad1_collision'>
          <pose frame=''>0 0 0 0 -0 0</pose>
          <geometry>
            <sphere>
              <radius>0.015</radius>
            </sphere>
          </geometry>
          <max_contacts>10</max_contacts>
          <surface>
            <contact/>
            <friction>
              <ode/>
            </friction>
          </surface>
        </collision>
        <visual name='right_pad1_visual'>
          <pose frame=''>0 0 0 0 -0 0</pose>
          <geometry>
            <sphere>
              <radius>0.015</radius>
            </sphere>
          </geometry>
        </visual>
        <self_collide>0</self_collide>
      </link>
      <joint name='right_foot_pad1' type='revolute'>
        <child>right_pad1</child>
        <parent>right_foot</parent>
        <axis>
          <xyz>1 0 0</xyz>
          <limit>
            <lower>0</lower>
            <upper>0</upper>
            <effort>1000</effort>
            <velocity>0.5</velocity>
          </limit>
          <dynamics>
            <spring_reference>0</spring_reference>
            <spring_stiffness>0</spring_stiffness>
          </dynamics>
          <use_parent_model_frame>1</use_parent_model_frame>
        </axis>
      </joint>
      <link name='right_pad2'>
        <pose frame=''>-0.08 0.127822 0.025537 0 -0 0</pose>
        <inertial>
          <pose frame=''>0 0 0 0 -0 0</pose>
          <mass>0.001</mass>
          <inertia>
            <ixx>0.01</ixx>
            <ixy>0</ixy>
            <ixz>0</ixz>
            <iyy>0.01</iyy>
            <iyz>0</iyz>
            <izz>0.01</izz>
          </inertia>
        </inertial>
        <collision name='right_pad2_collision'>
          <pose frame=''>0 0 0 0 -0 0</pose>
          <geometry>
            <sphere>
              <radius>0.015</radius>
            </sphere>
          </geometry>
          <max_contacts>10</max_contacts>
          <surface>
            <contact/>
            <friction>
              <ode/>
            </friction>
          </surface>
        </collision>
        <visual name='right_pad2_visual'>
          <pose frame=''>0 0 0 0 -0 0</pose>
          <geometry>
            <sphere>
              <radius>0.015</radius>
            </sphere>
          </geometry>
        </visual>
        <self_collide>0</self_collide>
      </link>
      <joint name='right_foot_pad2' type='revolute'>
        <child>right_pad2</child>
        <parent>right_foot</parent>
        <axis>
          <xyz>1 0 0</xyz>
          <limit>
            <lower>0</lower>
            <upper>0</upper>
            <effort>1000</effort>
            <velocity>0.5</velocity>
          </limit>
          <dynamics>
            <spring_reference>0</spring_reference>
            <spring_stiffness>0</spring_stiffness>
          </dynamics>
          <use_parent_model_frame>1</use_parent_model_frame>
        </axis>
      </joint>
      <link name='right_pad3'>
        <pose frame=''>0.08 0.127822 0.025537 0 -0 0</pose>
        <inertial>
          <pose frame=''>0 0 0 0 -0 0</pose>
          <mass>0.001</mass>
          <inertia>
            <ixx>0.01</ixx>
            <ixy>0</ixy>
            <ixz>0</ixz>
            <iyy>0.01</iyy>
            <iyz>0</iyz>
            <izz>0.01</izz>
          </inertia>
        </inertial>
        <collision name='right_pad3_collision'>
          <pose frame=''>0 0 0 0 -0 0</pose>
          <geometry>
            <sphere>
              <radius>0.015</radius>
            </sphere>
          </geometry>
          <max_contacts>10</max_contacts>
          <surface>
            <contact/>
            <friction>
              <ode/>
            </friction>
          </surface>
        </collision>
        <visual name='right_pad3_visual'>
          <pose frame=''>0 0 0 0 -0 0</pose>
          <geometry>
            <sphere>
              <radius>0.015</radius>
            </sphere>
          </geometry>
        </visual>
        <self_collide>0</self_collide>
      </link>
      <joint name='right_foot_pad3' type='revolute'>
        <child>right_pad3</child>
        <parent>right_foot</parent>
        <axis>
          <xyz>1 0 0</xyz>
          <limit>
            <lower>0</lower>
            <upper>0</upper>
            <effort>1000</effort>
            <velocity>0.5</velocity>
          </limit>
          <dynamics>
            <spring_reference>0</spring_reference>
            <spring_stiffness>0</spring_stiffness>
          </dynamics>
          <use_parent_model_frame>1</use_parent_model_frame>
        </axis>
      </joint>
      <link name='right_pad4'>
        <pose frame=''>0.08 0.187822 0.025537 0 -0 0</pose>
        <inertial>
          <pose frame=''>0 0 0 0 -0 0</pose>
          <mass>0.001</mass>
          <inertia>
            <ixx>0.01</ixx>
            <ixy>0</ixy>
            <ixz>0</ixz>
            <iyy>0.01</iyy>
            <iyz>0</iyz>
            <izz>0.01</izz>
          </inertia>
        </inertial>
        <collision name='right_pad4_collision'>
          <pose frame=''>0 0 0 0 -0 0</pose>
          <geometry>
            <sphere>
              <radius>0.015</radius>
            </sphere>
          </geometry>
          <max_contacts>10</max_contacts>
          <surface>
            <contact/>
            <friction>
              <ode/>
            </friction>
          </surface>
        </collision>
        <visual name='right_pad4_visual'>
          <pose frame=''>0 0 0 0 -0 0</pose>
          <geometry>
            <sphere>
              <radius>0.015</radius>
            </sphere>
          </geometry>
        </visual>
        <self_collide>0</self_collide>
      </link>
      <joint name='right_foot_pad4' type='revolute'>
        <child>right_pad4</child>
        <parent>right_foot</parent>
        <axis>
          <xyz>1 0 0</xyz>
          <limit>
            <lower>0</lower>
            <upper>0</upper>
            <effort>1000</effort>
            <velocity>0.5</velocity>
          </limit>
          <dynamics>
            <spring_reference>0</spring_reference>
            <spring_stiffness>0</spring_stiffness>
          </dynamics>
          <use_parent_model_frame>1</use_parent_model_frame>
        </axis>
      </joint>
      <static>0</static>
      <plugin name='gazebo_ros_control' filename='libgazebo_ros_control.so'>
        <robotNamespace>slider_gazebo</robotNamespace>
      </plugin>
      <pose frame=''>0 0 0 0 -0 0</pose>
    </model>
  </world>
</sdf>
