<?xml version="1.0"?>
<robot name="rotateSLIDER" xmlns:xacro="http://www.ros.org/wiki/xacro">

<gazebo>
  <plugin name="gazebo_ros_control" filename="libgazebo_ros_control.so">
    <robotNamespace>rotateSLIDER_Gazebo</robotNamespace>
    <legacyModeNS>true</legacyModeNS>
  </plugin>
</gazebo>

<!--xacro for some constant -->
<xacro:property name="base_height" value="0.62" />
<xacro:property name="ground_friction"   value="5.75"/>
<xacro:property name="stiffness_kp"   value="1.0e+8" />
<xacro:property name="stiffness_kd"   value="3.0e+6" />
<selfCollide>false</selfCollide>
<!--MAKE THE base MOVE in x-z plane -->
<link name="world"/>
<joint name="base_joint" type="floating"> 
  <origin rpy="0 0 0" xyz="0 0 0.63"/>
  <parent link="world"/>
  <child link="base"/>
</joint>

<link name="base">
  <visual>
    <geometry>
      <box size = "0.3 0.3 0.3"/>
    </geometry>
    <origin rpy="0 0 0" xyz="0 0 0"/>
  </visual>
  <collision>
    <geometry>
      <box size = "0.3 0.3 0.3"/>
    </geometry>
    <origin rpy="0 0 0" xyz="0 0 0"/>
  </collision> 
  <inertial>
    <mass value="15"/>
    <origin rpy="0 0 0" xyz="0.0 0 0"/>
    <inertia ixx="0.2250" ixy="0" ixz="0" iyy="0.2250" iyz="0" izz="0.2250"/>
  </inertial>
</link>

<joint name="right_hip_roll" type="revolute">
  <axis xyz="1 0 0"/>
  <limit effort="700.0" lower="-0.7853" upper="0.7853" velocity="3"/>
  <safety_controller k_velocity="30000" k_position="30000" soft_lower_limit="-0.6853" soft_upper_limit="0.6853" />
  <origin rpy="0 0 0" xyz="0 -0.15 0"/>
  <parent link="base"/>
  <child link="right_base_roll"/>
  <dynamics damping="0"/>
</joint>

<link name="right_base_roll">
  <visual>  
    <geometry>
      <cylinder radius="0.01" length="0.01"/>
    </geometry>
    <origin rpy="0 1.57 0" xyz="0 0 0"/>
  </visual>
 <!-- <collision>
    <geometry>
      <cylinder radius="0.01" length="0.01"/>
    </geometry>
    <origin rpy="0 0 0" xyz="0 0 0"/>
  </collision>  -->
  <inertial>
    <mass value="0.1"/>
    <origin rpy="0 1.57 0" xyz="0 0 0"/>
    <inertia ixx="0.033" ixy="0.0" ixz="0.0" iyy="0.033" iyz="0.0" izz="0.033"/>
  </inertial>
</link>

<joint name="right_hip_pitch" type="revolute">
  <axis xyz="0 1 0"/>
  <limit effort="700.0" velocity="3"/>
  <safety_controller k_velocity="300" k_position="15000"/>
  <origin rpy="0 0 0" xyz="0 0 0"/>
  <parent link="right_base_roll"/>
  <child link="right_base_pitch"/>
  <dynamics damping="0.9"/>
</joint>

<link name="right_base_pitch">
  <visual>  
    <geometry>
      <cylinder radius="0.01" length="0.01"/>
    </geometry>
    <origin rpy="1.57 0 0" xyz="0 0 0"/>
  </visual>
 <!-- <collision>
    <geometry>
      <cylinder radius="0.01" length="0.01"/>
    </geometry>
    <origin rpy="0 0 0" xyz="0 0 0"/>
  </collision>  -->
  <inertial>
    <mass value="0.1"/>
    <origin rpy="1.57 0 0" xyz="0 0 0"/>
    <inertia ixx="0.033" ixy="0.0" ixz="0.0" iyy="0.033" iyz="0.0" izz="0.033"/>
  </inertial>
</link>

<joint name="right_hip_slide" type="prismatic">
  <axis xyz="0 0 -1"/>
  <limit effort="6000.0" lower="-0.6" upper="0.6" velocity="400"/>
  <safety_controller k_velocity="300" k_position="6000" soft_lower_limit="-0.6" soft_upper_limit="0.6" />
  <origin rpy="0 0.0 0" xyz="0 -0.02 0"/>
  <!-- <origin rpy="0 0.0 0" xyz="0 -0.02 -0.18"/> -->
  <parent link="right_base_pitch"/>
  <child link="right_leg"/>
  <dynamics damping="0.7"/>
</joint>

<link name="right_leg">
  <visual>
    <geometry>
      <cylinder radius="0.02" length="1.2"/>
    </geometry>
    <origin rpy="0 0 0" xyz="0 0 0.0"/>
  </visual>
  <collision>
    <geometry>
      <cylinder radius="0.02" length="1.2"/>
    </geometry>
    <origin rpy="0 0 0" xyz="0 0 0.0"/>
  </collision>
  <inertial>
    <mass value="0.3"/>
    <origin rpy="0 0 0" xyz="0 0 0.0"/>
    <inertia ixx="0.012" ixy="0.0" ixz="0.0" iyy="0.012" iyz="0" izz="0.00"/>
  </inertial>
</link>

<joint name="rightLegTopFootJoint" type="fixed">
  <origin rpy="0 0 0" xyz="0 0 0.6"/>
  <parent link="right_leg"/>
  <child link="rightTopFoot"/>
</joint>

<link name="rightTopFoot">
  <visual>
    <geometry>
      <sphere radius = "0.02"/>
    </geometry>
    <origin rpy="0 0 0" xyz="0 0 0.0"/>
  </visual>
  <collision>
    <geometry>
      <sphere radius = "0.02"/>
    </geometry>
    <origin rpy="0 0 0" xyz="0.0 0 0.0"/>
    <!-- <surface>
      <friction>
        <ode>
          <mu>100</mu>
          <mu2>10000</mu2>
        </ode>
      </friction>
    </surface> -->
  </collision> 
  <inertial>
    <mass value="0.005"/>
    <origin rpy="0 0 0" xyz="0.0 0 0.0"/>
    <inertia ixx="0.0016" ixy="0" ixz="0" iyy="0.0016" iyz="0" izz="0.0016"/>
  </inertial>
</link>

<joint name="rightLegBottomFootJoint" type="fixed">
  <origin rpy="0 0 0" xyz="0 0 -0.6"/>
  <parent link="right_leg"/>
  <child link="rightBottomFoot"/>
</joint>

<link name="rightBottomFoot">
  <visual>
    <geometry>
      <sphere radius = "0.02"/>
    </geometry>
    <origin rpy="0 0 0" xyz="0 0 0.0"/>
  </visual>
  <collision>
    <geometry>
      <sphere radius = "0.02"/>
    </geometry>
    <surface>
      <friction>
        <ode>
          <mu>${ground_friction}</mu>
          <mu2>${ground_friction}</mu2>
        </ode>
      </friction>
    </surface>
    <origin rpy="0 0 0" xyz="0.0 0 0.0"/>
  </collision> 
  <inertial>
    <mass value="0.005"/>
    <origin rpy="0 0 0" xyz="0.0 0 0.0"/>
    <inertia ixx="0.0016" ixy="0" ixz="0" iyy="0.0016" iyz="0" izz="0.0016"/>
  </inertial>
</link>

<!-- Left Leg Part -->
<joint name="left_hip_roll" type="revolute">
  <axis xyz="1 0 0"/>
  <limit effort="700.0" lower="-0.7853" upper="0.7853" velocity="3"/>
  <safety_controller k_velocity="30000" k_position="30000" soft_lower_limit="-0.6853" soft_upper_limit="0.6853" />
  <origin rpy="0 0 0" xyz="0 0.15 0"/>
  <parent link="base"/>
  <child link="left_base_roll"/>
  <dynamics damping="0"/>
</joint>

<link name="left_base_roll">
  <visual>  
    <geometry>
      <cylinder radius="0.01" length="0.01"/>
    </geometry>
    <origin rpy="0 1.57 0" xyz="0 0 0"/>
  </visual>
 <!-- <collision>
    <geometry>
      <cylinder radius="0.01" length="0.01"/>
    </geometry>
    <origin rpy="0 0 0" xyz="0 0 0"/>
  </collision>  -->
  <inertial>
    <mass value="0.1"/>
    <origin rpy="0 1.57 0" xyz="0 0 0"/>
    <inertia ixx="0.033" ixy="0.0" ixz="0.0" iyy="0.033" iyz="0.0" izz="0.033"/>
  </inertial>
</link>

<joint name="left_hip_pitch" type="revolute">
  <axis xyz="0 1 0"/>
  <limit effort="700.0" velocity="3"/>
  <safety_controller k_velocity="300" k_position="15000" />
  <origin rpy="0 0 0" xyz="0 0 0"/>
  <parent link="left_base_roll"/>
  <child link="left_base_pitch"/>
  <dynamics damping="0.9"/>
</joint>

<link name="left_base_pitch">
  <visual>  
    <geometry>
      <cylinder radius="0.01" length="0.01"/>
    </geometry>
    <origin rpy="1.57 0 0" xyz="0 0 0"/>
  </visual>
 <!-- <collision>
    <geometry>
      <cylinder radius="0.01" length="0.01"/>
    </geometry>
    <origin rpy="0 0 0" xyz="0 0 0"/>
  </collision>  -->
  <inertial>
    <mass value="0.1"/>
    <origin rpy="1.57 0 0" xyz="0 0 0"/>
    <inertia ixx="0.033" ixy="0.0" ixz="0.0" iyy="0.033" iyz="0.0" izz="0.033"/>
  </inertial>
</link>

<joint name="left_hip_slide" type="prismatic">
  <axis xyz="0 0 -1"/>
  <limit effort="6000.0" lower="-0.6" upper="0.6" velocity="400"/>
  <safety_controller k_velocity="300" k_position="6000" soft_lower_limit="-0.6" soft_upper_limit="0.6" />
  <origin rpy="0 0.0 0" xyz="0 0.02 0.0"/>
  <!-- <origin rpy="0 -0.0 0" xyz="0 0.02 -0.18"/> -->
  <parent link="left_base_pitch"/>
  <child link="left_leg"/>
  <dynamics damping="0"/>
</joint>

<link name="left_leg">
  <visual>
    <geometry>
      <cylinder radius="0.02" length="1.2"/>
    </geometry>
    <origin rpy="0 0 0" xyz="0 0 0.0"/>
  </visual>
  <collision>
    <geometry>
      <cylinder radius="0.02" length="1.2"/>
    </geometry>
    <origin rpy="0 0 0" xyz="0 0 0.0"/>
  </collision>
  <inertial>
    <mass value="0.3"/>
    <origin rpy="0 0 0" xyz="0 0 0.0"/>
    <inertia ixx="0.012" ixy="0.0" ixz="0.0" iyy="0.012" iyz="0" izz="0.00"/>
  </inertial>
</link>

<joint name="leftLegTopFootJoint" type="fixed">
  <origin rpy="0 0 0" xyz="0 0 0.6"/>
  <parent link="left_leg"/>
  <child link="leftTopFoot"/>
</joint>

<link name="leftTopFoot">
  <visual>
    <geometry>
      <sphere radius = "0.02"/>
    </geometry>
    <origin rpy="0 0 0" xyz="0 0 0.0"/>
  </visual>
  <collision>
    <geometry>
      <sphere radius = "0.02"/>
    </geometry>
    <origin rpy="0 0 0" xyz="0.0 0 0.0"/>
  </collision> 
  <inertial>
    <mass value="0.005"/>
    <origin rpy="0 0 0" xyz="0.0 0 0.0"/>
    <inertia ixx="0.0016" ixy="0" ixz="0" iyy="0.0016" iyz="0" izz="0.0016"/>
  </inertial>
</link>

<joint name="leftLegBottomFootJoint" type="fixed">
  <origin rpy="0 0 0" xyz="0 0 -0.6"/>
  <parent link="left_leg"/>
  <child link="leftBottomFoot"/>
</joint>

<link name="leftBottomFoot">
  <visual>
    <geometry>
      <sphere radius = "0.02"/>
    </geometry>
    <origin rpy="0 0 0" xyz="0 0 0.0"/>
  </visual>
  <collision>
    <geometry>
      <sphere radius = "0.02"/>
    </geometry>
    <surface>
      <friction>
        <ode>
          <mu>${ground_friction}</mu>
          <mu2>${ground_friction}</mu2>
        </ode>
      </friction>
    </surface>
    <origin rpy="0 0 0" xyz="0.0 0 0.0"/>
  </collision> 
  <inertial>
    <mass value="0.005"/>
    <origin rpy="0 0 0" xyz="0.0 0 0.0"/>
    <inertia ixx="0.0016" ixy="0" ixz="0" iyy="0.0016" iyz="0" izz="0.0016"/>
  </inertial>
</link>

<gazebo reference="rightTopFoot">
  <kp value = "${stiffness_kp}"/>
  <kd value = "${stiffness_kd}"/>
  <collision>
    <surface>
      <friction>
        <ode>
          <mu>10000000</mu>
          <mu2>100000</mu2>
        </ode>
      </friction>
    </surface>
  </collision> 
</gazebo>
<gazebo reference="rightBottomFoot">
  <kp value = "${stiffness_kp}"/>
  <kd value = "${stiffness_kd}"/>
  <collision>
    <surface>
      <friction>
        <ode>
          <mu>10000000</mu>
          <mu2>100000</mu2>
        </ode>
      </friction>
    </surface>
  </collision> 
</gazebo>
<gazebo reference="leftTopFoot">
  <kp value = "${stiffness_kp}"/>
  <kd value = "${stiffness_kd}"/>
  <collision>
    <surface>
      <friction>
        <ode>
          <mu>10000000</mu>
          <mu2>100000</mu2>
        </ode>
      </friction>
    </surface>
  </collision> 
</gazebo>
<gazebo reference="leftBottomFoot">
  <kp value = "${stiffness_kp}"/>
  <kd value = "${stiffness_kd}"/>
  <collision>
    <surface>
      <friction>
        <ode>
          <mu>10000000</mu>
          <mu2>100000</mu2>
        </ode>
      </friction>
    </surface>
  </collision> 
</gazebo>
<gazebo reference="base">
  <kp value = "${stiffness_kp}"/>
  <kd value = "${stiffness_kd}"/>
  <collision>
    <surface>
      <friction>
        <ode>
          <mu>100</mu>
          <mu2>100</mu2>
        </ode>
      </friction>
    </surface>
  </collision> 
</gazebo>

<gazebo reference="rightTopFoot">
  <!-- <material>Gazebo/Blue</material> -->
  <material>Gazebo/Red</material>
</gazebo>
<gazebo reference="rightBottomFoot">
  <!-- <material>Gazebo/Blue</material> -->
  <material>Gazebo/Yellow</material>
</gazebo>
<gazebo reference="leftTopFoot">
  <!-- <material>Gazebo/Blue</material> -->
  <material>Gazebo/Green</material>
</gazebo>
<gazebo reference="leftBottomFoot">
  <!-- <material>Gazebo/Blue</material> -->
  <material>Gazebo/Blue</material>
</gazebo>

<!-- Transmissions used for ros_control -->
<transmission name="tran1">
  <type>transmission_interface/SimpleTransmission</type>
  <joint name="left_hip_pitch">
    <hardwareInterface>hardware_interface/EffortJointInterface</hardwareInterface>
  </joint>
  <actuator name="motor1">
    <hardwareInterface>hardware_interface/EffortJointInterface</hardwareInterface>
    <mechanicalReduction>1</mechanicalReduction>
  </actuator>
</transmission>

<transmission name="tran2">
  <type>transmission_interface/SimpleTransmission</type>
  <joint name="left_hip_roll">
    <hardwareInterface>hardware_interface/EffortJointInterface</hardwareInterface>
  </joint>
  <actuator name="motor2">
    <hardwareInterface>hardware_interface/EffortJointInterface</hardwareInterface>
    <mechanicalReduction>1</mechanicalReduction>
  </actuator>
</transmission>

<transmission name="tran3">
  <type>transmission_interface/SimpleTransmission</type>
  <joint name="left_hip_slide">
    <hardwareInterface>hardware_interface/EffortJointInterface</hardwareInterface>
  </joint>
  <actuator name="motor3">
    <hardwareInterface>hardware_interface/EffortJointInterface</hardwareInterface>
    <mechanicalReduction>1</mechanicalReduction>
  </actuator>
</transmission>

<transmission name="tran4">
  <type>transmission_interface/SimpleTransmission</type>
  <joint name="right_hip_pitch">
    <hardwareInterface>hardware_interface/EffortJointInterface</hardwareInterface>
  </joint>
  <actuator name="motor4">
    <hardwareInterface>hardware_interface/EffortJointInterface</hardwareInterface>
    <mechanicalReduction>1</mechanicalReduction>
  </actuator>
</transmission>

<transmission name="tran5">
  <type>transmission_interface/SimpleTransmission</type>
  <joint name="right_hip_roll">
    <hardwareInterface>hardware_interface/EffortJointInterface</hardwareInterface>
  </joint>
  <actuator name="motor5">
    <hardwareInterface>hardware_interface/EffortJointInterface</hardwareInterface>
    <mechanicalReduction>1</mechanicalReduction>
  </actuator>
</transmission>

<transmission name="tran6">
  <type>transmission_interface/SimpleTransmission</type>
  <joint name="right_hip_slide">
    <hardwareInterface>hardware_interface/EffortJointInterface</hardwareInterface>
  </joint>
  <actuator name="motor6">
    <hardwareInterface>hardware_interface/EffortJointInterface</hardwareInterface>
    <mechanicalReduction>1</mechanicalReduction>
  </actuator>
</transmission>

</robot>