<?xml version="1.0"?>
<robot name="slider" xmlns:xacro="http://www.ros.org/wiki/xacro">

<gazebo>
  <plugin name="gazebo_ros_control" filename="libgazebo_ros_control.so">
    <robotNamespace>slider_gazebo</robotNamespace>
    <legacyModeNS>true</legacyModeNS>
  </plugin>
</gazebo>

<!-- When the joint is near the soft limits, the possible velocities are bounded to keep the 
     position from crossing the soft limits. -->

<!--xacro for some constant -->
<xacro:property name="pelvis_height" value="0.8" />
<xacro:property name="right_offset"  value="-0.167" />
<xacro:property name="left_offset"   value="0.167" />
<xacro:property name="ground_friction"   value="0.75"/>
<xacro:property name="stiffness_kp"   value="1.0e+5" />
<xacro:property name="stiffness_kd"   value="1.0e+3" />

<selfCollide>false</selfCollide>

<!--MAKE THE pelvis FIXED in the air -->
  <link name="world"/>

  <joint name="base_joint" type="floating">
    <origin rpy="0 0 0" xyz="0 0 ${pelvis_height}"/>
    <parent link="world"/>
    <child link="pelvis"/>
  </joint>

  <link name="pelvis">
    <visual>
      <geometry>
        <box size = "0.26 0.334 0.18"/>
      </geometry>
      <origin rpy="0 0 0" xyz="0 0 0"/>
    </visual>
    <collision>
      <geometry>
        <box size = "0.26 0.334 0.18"/>
      </geometry>
      <origin rpy="0 0 0" xyz="0.06 0 0"/>
    </collision>
    <inertial>
      <mass value="8.5"/>
      <origin rpy="0 0 0" xyz="0.0 0 0"/>
      <inertia ixx="0.1020" ixy="0" ixz="0" iyy="0.0708" iyz="0" izz="0.1269"/> 
      <!-- <inertia ixx="0.137215" ixy="0" ixz="0" iyy="0.132175" iyz="0" izz="0.13696"/> -->
    </inertial>
  </link>

  <joint name="right_hip_roll" type="revolute">
    <axis xyz="1 0 0"/>
    <limit effort="700.0" lower="-0.7853" upper="0.7853" velocity="3"/>
    <safety_controller k_velocity="300" k_position="15000" soft_lower_limit="-0.6853" soft_upper_limit="0.6853" />
    <origin rpy="0 0 0" xyz="0 -0.167 0"/>
    <parent link="pelvis"/>
    <child link="right_base_roll"/>
    <dynamics damping="0.7"/>
  </joint>

  <link name="right_base_roll">
    <visual>  
      <geometry>
        <cylinder radius="0.04" length="0.212"/>
      </geometry>
      <origin rpy="0 1.57 0" xyz="0 0 0"/>
    </visual>
<!--     <collision>
      <geometry>
        <cylinder radius="0.01" length="0.01"/>
      </geometry>
      <origin rpy="0 0 0" xyz="0 0 0"/>
    </collision> -->
    <inertial>
      <mass value="1"/>
      <origin rpy="0 1.57 0" xyz="0 0 0"/>
      <inertia ixx="0.0041" ixy="0.0" ixz="0.0" iyy="0.0041" iyz="0.0" izz="0.0008"/>
    </inertial>
  </link>

  <joint name="right_hip_pitch" type="revolute">
    <axis xyz="0 1 0"/>
    <limit effort="300.0" lower="-0.7853" upper="0.7853" velocity="999"/>
    <safety_controller k_velocity="300" k_position="30000" soft_lower_limit="-0.6853" soft_upper_limit="0.6853" />
    <origin rpy="0 0 0" xyz="0 0 0"/>
    <parent link="right_base_roll"/>
    <child link="right_base_pitch"/>
    <dynamics damping="0.7"/>
  </joint>

  <link name="right_base_pitch">
    <visual>	
      <geometry>
        <cylinder radius="0.04" length="0.212"/>
      </geometry>
      <origin rpy="1.57 0 0" xyz="0 0 0"/>
    </visual>
<!--     <collision>
      <geometry>
        <cylinder radius="0.04" length="0.17"/>
      </geometry>
      <origin rpy="1.57 0 0" xyz="0 0 0"/>
    </collision> -->
    <inertial>
      <mass value="0.003"/>
      <origin rpy="1.57 0 0" xyz="0 0 0"/>
      <inertia ixx="0.004145" ixy="0.0" ixz="0.0" iyy="0.004145" iyz="0.0" izz="0.0008"/>
    </inertial>
  </link>

  <joint name="right_hip_slide" type="prismatic">
    <axis xyz="0 0 -1"/>
    <limit effort="600.0" lower="0" upper="1.2" velocity="4"/>
    <safety_controller k_velocity="300" k_position="6000" soft_lower_limit="0.1" soft_upper_limit="1.1" />
    <origin rpy="0 0 0" xyz="0 -0.106 -0.15"/>
    <parent link="right_base_pitch"/>
    <child link="right_leg"/>
    <dynamics damping="0.7"/>
  </joint>

  <link name="right_leg">
    <visual>
      <geometry>
        <cylinder radius="0.021" length="1.2"/>
      </geometry>
      <origin rpy="0 0 0" xyz="0 0 0.0"/>
    </visual>
    <collision>
      <geometry>
        <cylinder radius="0.021" length="1.2"/>
      </geometry>
      <origin rpy="0 0 0" xyz="0 0 0.0"/>
    </collision>
    <inertial>
      <mass value="1.5"/>
      <origin rpy="0 0 0" xyz="0 0 0.0"/>
      <!-- cannot make smaller because of unstable behaviour-->
      <inertia ixx="0.1802" ixy="0.0" ixz="0.0" iyy="0.1802" iyz="0" izz="0.0003"/>
    </inertial>
  </link>

  <joint name="right_ankle_pitch" type="revolute">
    <axis xyz="0 1 0"/>
    <limit effort="50.0" lower="-0.7853" upper="0.7853" velocity="999"/>
    <safety_controller k_velocity="300" k_position="15000" soft_lower_limit="-0.6853" soft_upper_limit="0.6853" />
    <origin rpy="0 0 0" xyz="0 0 -0.62"/>
    <parent link="right_leg"/>
    <child link="right_ankle_pitch_link"/>
    <dynamics damping="0.7"/>
  </joint>

 <link name="right_ankle_pitch_link">
    <visual>  
      <geometry>
        <cylinder radius="0.01" length="0.06"/>
      </geometry>
      <origin rpy="1.57 0 0" xyz="0 0 0"/>
    </visual>
    <collision>
      <geometry>
        <cylinder radius="0.01" length="0.06"/>
      </geometry>
      <origin rpy="1.57 0 0" xyz="0 0 0"/>
    </collision>
    <inertial>
      <mass value="0.01"/>
      <origin rpy="1.57 0 0" xyz="0 0 0"/>
      <inertia ixx="0.003250" ixy="0.0" ixz="0.0" iyy="0.003250" iyz="0.0" izz="0.000500"/>
    </inertial>
  </link>

  <joint name="right_ankle_roll" type="revolute">
    <axis xyz="1 0 0"/>
    <limit effort="50.0" lower="-0.6" upper="0.6" velocity="3.0"/>
    <safety_controller k_velocity="300" k_position="15000" soft_lower_limit="-0.4" soft_upper_limit="0.4" />
    <origin rpy="0 0 0" xyz="0 0 -0.025"/>
    <parent link="right_ankle_pitch_link"/>
    <child link="right_foot"/>
    <dynamics damping="0.7"/>
  </joint>

  <!--link name="right_ankle_roll_link">
    <visual>  
      <geometry>
        <cylinder radius="0.01" length="0.06"/>
      </geometry>
      <origin rpy="0 1.57 0" xyz="0 0 0"/>
    </visual>
    <collision>
      <geometry>
        <cylinder radius="0.01" length="0.06"/>
      </geometry>
      <origin rpy="0 1.57 0" xyz="0 0 0"/>
    </collision>
    <inertial>
      <mass value="0.32"/>
      <origin rpy="0 1.57 0" xyz="0 0 0"/>
      <inertia ixx="0.0014" ixy="0.0" ixz="0.0" iyy="0.0014" iyz="0.0" izz="0.0007"/>
      <inertia ixx="0.0254" ixy="0.0" ixz="0.0" iyy="0.0254" iyz="0.0" izz="0.0117"/> 
    </inertial>
  </link-->

  <!--joint name="right_foot_ankle_joint" type="fixed">
    <origin rpy="0 0 0" xyz="0 0 -0.025"/>
    <parent link="right_ankle_roll_link"/>
    <child link="right_foot"/>
  </joint-->

 <link name="right_foot">
    <visual>  
      <geometry>
        <box size = "0.205 0.15 0.01"/>
      </geometry>
      <origin rpy="0 0 0" xyz="0 0 0"/>
    </visual>
    <collision>
      <geometry>
        <box size = "0.205 0.15 0.01"/>
      </geometry>
      <origin rpy="0 0 0" xyz="0 0 0"/>
      <!-- <surface>
        <friction>
          <ode>
            <mu>${ground_friction}</mu>
            <mu2>${ground_friction}</mu2>
          </ode>
        </friction>
      </surface> -->
    </collision>
    <inertial>
      <mass value="0.28"/>
      <origin rpy="0 0 0" xyz="0 0 0"/>
      <inertia ixx="0.0005" ixy="0" ixz="0" iyy="0.0010" iyz="0" izz="0.0015"/>
      <!-- <inertia ixx="0.0056" ixy="0" ixz="0" iyy="0.0056" iyz="0" izz="0.014"/> -->
    </inertial>
  </link>

<!-- left part -->
  <link name="left_base_roll">
    <visual>  
      <geometry>
        <cylinder radius="0.04" length="0.212"/>
      </geometry>
      <origin rpy="0 1.57 0" xyz="0 0 0"/>
    </visual>
<!--     <collision>
      <geometry>
        <cylinder radius="0.01" length="0.01"/>
      </geometry>
      <origin rpy="0 0 0" xyz="0 0 0"/>
    </collision> -->
    <inertial>
      <mass value="1"/>
      <origin rpy="0 1.57 0" xyz="0 0 0"/>
      <inertia ixx="0.0041" ixy="0.0" ixz="0.0" iyy="0.0041" iyz="0.0" izz="0.0008"/>
      <!-- <inertia ixx="0.0254" ixy="0.0" ixz="0.0" iyy="0.0254" iyz="0.0" izz="0.0117"/> -->
    </inertial>
  </link>

  <joint name="left_hip_roll" type="revolute">
    <axis xyz="1 0 0"/>
    <limit effort="700.0" lower="-0.7853" upper="0.7853" velocity="3"/>
    <safety_controller k_velocity="300" k_position="25000" soft_lower_limit="-0.6853" soft_upper_limit="0.6853"/>
    <origin rpy="0 0 0" xyz="0 0.167 0"/>
    <parent link="pelvis"/>
    <child link="left_base_roll"/>
    <dynamics damping="0.7"/>
  </joint>

  <link name="left_base_pitch">
    <visual>	
      <geometry>
        <cylinder radius="0.04" length="0.212"/>
      </geometry>
      <material name="white"/>
      <origin rpy="1.57 0 0" xyz="0 0 0"/>
    </visual>
<!--     <collision>
      <geometry>
        <cylinder radius="0.04" length="0.17"/>
      </geometry>
      <origin rpy="1.57 0 0" xyz="0 0 0"/>
    </collision> -->
    <inertial>
      <mass value="0.01"/>
      <origin rpy="0 0 0" xyz="0 0 0"/>
      <inertia ixx="0.004145" ixy="0.0" ixz="0.0" iyy="0.004145" iyz="0.0" izz="0.0008"/>
      <!-- <inertia ixx="0.0254" ixy="0.0" ixz="0.0" iyy="0.0254" iyz="0.0" izz="0.0117"/> -->
    </inertial>
  </link>

  <joint name="left_hip_pitch" type="revolute">
    <axis xyz="0 1 0"/>
    <limit effort="300.0" lower="-0.7853" upper="0.7853" velocity="999"/>
    <safety_controller k_velocity="300" k_position="30000" soft_lower_limit="-0.6853" soft_upper_limit="0.6853"/>
    <origin rpy="0 0 0" xyz="0 0 0"/>
    <parent link="left_base_roll"/>
    <child link="left_base_pitch"/>
    <dynamics damping="0.7"/>
  </joint>

  <link name="left_leg">
    <visual>
      <geometry>
        <cylinder radius="0.021" length="1.2"/>
      </geometry>
      <origin rpy="0 0 0" xyz="0 0 0.0"/>
      <material name="black"/>
    </visual>
    <collision>
      <geometry>
        <cylinder radius="0.021" length="1.2"/>
      </geometry>
      <origin rpy="0 0 0" xyz="0 0 0.0"/>
    </collision>
    <inertial>
      <mass value="1.5"/>
      <origin rpy="0 0 0" xyz="0 0 0.0"/>
      <!-- cannot make smaller because some behaviour unstable -->
      <inertia ixx="0.1802" ixy="0.0" ixz="0.0" iyy="0.1802" iyz="0" izz="0.0003"/>
    </inertial>
  </link>

  <joint name="left_hip_slide" type="prismatic">
    <axis xyz="0 0 -1"/>
    <limit effort="600.0" lower="0" upper="1.2" velocity="4"/>
    <safety_controller k_velocity="300" k_position="6000" soft_lower_limit="0.1" soft_upper_limit="1.1" />
    <origin rpy="0 0 0" xyz="0 0.106 -0.15"/>
    <parent link="left_base_pitch"/>
    <child link="left_leg"/>
    <dynamics damping="0.7"/>
  </joint>

  <joint name="left_ankle_pitch" type="revolute">
    <axis xyz="0 1 0"/>
    <limit effort="50.0" lower="-0.7853" upper="0.7853" velocity="999"/>
    <safety_controller k_velocity="300" k_position="15000" soft_lower_limit="-0.6853" soft_upper_limit="0.6853" />
    <origin rpy="0 0 0" xyz="0 0 -0.62"/>
    <parent link="left_leg"/>
    <child link="left_ankle_pitch_link"/>
    <dynamics damping="0.7"/>
  </joint>

  <link name="left_ankle_pitch_link">
    <visual>  
      <geometry>
        <cylinder radius="0.01" length="0.06"/>
      </geometry>
      <origin rpy="1.57 0 0" xyz="0 0 0"/>
    </visual>
    <collision>
      <geometry>
        <cylinder radius="0.01" length="0.06"/>
      </geometry>
      <origin rpy="1.57 0 0" xyz="0 0 0"/>
    </collision>
    <inertial>
      <mass value="0.01"/>
      <origin rpy="1.57 0 0" xyz="0 0 0"/>
      <inertia ixx="0.003250" ixy="0.0" ixz="0.0" iyy="0.003250" iyz="0.0" izz="0.000500"/>
    </inertial>
  </link>

  <joint name="left_ankle_roll" type="revolute">
    <axis xyz="1 0 0"/>
    <limit effort="50.0" lower="-0.6" upper="0.6" velocity="3.0"/>
    <safety_controller k_velocity="300" k_position="15000" soft_lower_limit="-0.4" soft_upper_limit="0.4" />
    <origin rpy="0 0 0" xyz="0 0 -0.025"/>
    <parent link="left_ankle_pitch_link"/>
    <child link="left_foot"/>
    <dynamics damping="0.7"/>
  </joint>

  <link name="left_foot">
    <visual>  
      <geometry>
        <box size = "0.205 0.15 0.01"/>
      </geometry>
      <origin rpy="0 0 0" xyz="0 0 0.0"/>
    </visual>
    <collision>
      <geometry>
        <box size = "0.205 0.15 0.01"/>
      </geometry>
      <origin rpy="0 0 0" xyz="0 0 0"/>
      <!-- <surface>
        <friction>
          <ode>
            <mu>${ground_friction}</mu>
            <mu2>${ground_friction}</mu2>
          </ode>
        </friction>
      </surface> -->
    </collision>
    <inertial>
      <mass value="0.28"/>
      <origin rpy="0 0 0" xyz="0 0 0.0"/>
      <inertia ixx="0.0005" ixy="0" ixz="0" iyy="0.0010" iyz="0" izz="0.0015"/>
      <!-- <inertia ixx="0.0056" ixy="0" ixz="0" iyy="0.0056" iyz="0" izz="0.014"/> -->
    </inertial>
  </link>

  <gazebo reference="left_foot">
    <kp value = "${stiffness_kp}"/>
    <kd value = "${stiffness_kd}"/>
  </gazebo>

  <gazebo reference="right_foot">
    <kp value = "${stiffness_kp}"/>
    <kd value = "${stiffness_kd}"/>
  </gazebo>


<!-- assign colors to different parts of SLIDER -->
  <gazebo reference="pelvis">
    <!-- <material>Gazebo/Yellow</material> -->
    <material>Gazebo/White</material>
  </gazebo>

  <gazebo reference="torsoCasing">
    <!-- <material>Gazebo/Orange</material> -->
    <!-- <material>Gazebo/Red</material> -->
    <material>Gazebo/White</material>
  </gazebo>

  <gazebo reference="left_base_pitch">
    <!-- <material>Gazebo/Blue</material> -->
    <material>Gazebo/Purple</material>
  </gazebo>
  <gazebo reference="right_base_pitch">
    <!-- <material>Gazebo/Red</material> -->
    <material>Gazebo/Purple</material>
  </gazebo>

  <gazebo reference="left_base_roll">
    <!-- <material>Gazebo/Blue</material> -->
    <material>Gazebo/Red</material>
  </gazebo>
  <gazebo reference="right_base_roll">
    <!-- <material>Gazebo/Red</material> -->
    <material>Gazebo/Red</material>
  </gazebo>

  <gazebo reference="right_leg">
    <!-- <material>Gazebo/Red</material> -->
    <material>Gazebo/White</material>
  </gazebo>
<!--   <gazebo reference="right_ankle_offset">
    <material>Gazebo/White</material>
  </gazebo> --> 
  <gazebo reference="right_ankle_pitch_link">
    <!-- <material>Gazebo/Red</material> -->
    <material>Gazebo/Purple</material>
  </gazebo>
  <gazebo reference="right_ankle_roll_link">
    <!-- <material>Gazebo/Red</material> -->
    <material>Gazebo/Red</material>
  </gazebo>

  <gazebo reference="right_foot">
    <!-- <material>Gazebo/Red</material> -->
    <material>Gazebo/White</material>
  </gazebo>

  <gazebo reference="left_leg">
    <material>Gazebo/White</material>
    <!-- <material>Gazebo/Blue</material> -->
  </gazebo>
<!--   <gazebo reference="left_ankle_offset">
    <material>Gazebo/Blue</material>
    <material>Gazebo/White</material>
  </gazebo> -->
  <gazebo reference="left_ankle_roll_link">
    <!-- <material>Gazebo/Blue</material> -->
    <material>Gazebo/Red</material>
  </gazebo>
  <gazebo reference="left_ankle_pitch_link">
    <!-- <material>Gazebo/Blue</material> -->
    <material>Gazebo/Purple</material>
  </gazebo>
  <gazebo reference="left_foot">
    <!-- <material>Gazebo/Blue</material> -->
    <material>Gazebo/White</material>
  </gazebo>

  <!-- Transmissions used for ros_control -->
  <transmission name="tran1">
    <type>transmission_interface/SimpleTransmission</type>
    <joint name="left_hip_pitch">
      <hardwareInterface>hardware_interface/EffortJointInterface</hardwareInterface>
    </joint>
    <actuator name="motor1">
      <hardwareInterface>hardware_interface/EffortJointInterface</hardwareInterface>
      <mechanicalReduction>1</mechanicalReduction>
    </actuator>
  </transmission>

  <transmission name="tran2">
    <type>transmission_interface/SimpleTransmission</type>
    <joint name="left_hip_roll">
      <hardwareInterface>hardware_interface/EffortJointInterface</hardwareInterface>
    </joint>
    <actuator name="motor2">
      <hardwareInterface>hardware_interface/EffortJointInterface</hardwareInterface>
      <mechanicalReduction>1</mechanicalReduction>
    </actuator>
  </transmission>

  <transmission name="tran3">
    <type>transmission_interface/SimpleTransmission</type>
    <joint name="left_hip_slide">
      <hardwareInterface>hardware_interface/EffortJointInterface</hardwareInterface>
    </joint>
    <actuator name="motor3">
      <hardwareInterface>hardware_interface/EffortJointInterface</hardwareInterface>
      <mechanicalReduction>1</mechanicalReduction>
    </actuator>
  </transmission>

  <transmission name="tran4">
    <type>transmission_interface/SimpleTransmission</type>
    <joint name="left_ankle_pitch">
      <hardwareInterface>hardware_interface/EffortJointInterface</hardwareInterface>
    </joint>
    <actuator name="motor4">
      <hardwareInterface>hardware_interface/EffortJointInterface</hardwareInterface>
      <mechanicalReduction>1</mechanicalReduction>
    </actuator>
  </transmission>

  <transmission name="tran5">
    <type>transmission_interface/SimpleTransmission</type>
    <joint name="left_ankle_roll">
      <hardwareInterface>hardware_interface/EffortJointInterface</hardwareInterface>
    </joint>
    <actuator name="motor5">
      <hardwareInterface>hardware_interface/EffortJointInterface</hardwareInterface>
      <mechanicalReduction>1</mechanicalReduction>
    </actuator>
  </transmission>

  <transmission name="tran6">
    <type>transmission_interface/SimpleTransmission</type>
    <joint name="right_hip_pitch">
      <hardwareInterface>hardware_interface/EffortJointInterface</hardwareInterface>
    </joint>
    <actuator name="motor6">
      <hardwareInterface>hardware_interface/EffortJointInterface</hardwareInterface>
      <mechanicalReduction>1</mechanicalReduction>
    </actuator>
  </transmission>

  <transmission name="tran7">
    <type>transmission_interface/SimpleTransmission</type>
    <joint name="right_hip_roll">
      <hardwareInterface>hardware_interface/EffortJointInterface</hardwareInterface>
    </joint>
    <actuator name="motor7">
      <hardwareInterface>hardware_interface/EffortJointInterface</hardwareInterface>
      <mechanicalReduction>1</mechanicalReduction>
    </actuator>
  </transmission>

  <transmission name="tran8">
    <type>transmission_interface/SimpleTransmission</type>
    <joint name="right_hip_slide">
      <hardwareInterface>hardware_interface/EffortJointInterface</hardwareInterface>
    </joint>
    <actuator name="motor8">
      <hardwareInterface>hardware_interface/EffortJointInterface</hardwareInterface>
      <mechanicalReduction>1</mechanicalReduction>
    </actuator>
  </transmission>

  <transmission name="tran9">
    <type>transmission_interface/SimpleTransmission</type>
    <joint name="right_ankle_pitch">
      <hardwareInterface>hardware_interface/EffortJointInterface</hardwareInterface>
    </joint>
    <actuator name="motor9">
      <hardwareInterface>hardware_interface/EffortJointInterface</hardwareInterface>
      <mechanicalReduction>1</mechanicalReduction>
    </actuator>
  </transmission>

  <transmission name="tran10">
    <type>transmission_interface/SimpleTransmission</type>
    <joint name="right_ankle_roll">
      <hardwareInterface>hardware_interface/EffortJointInterface</hardwareInterface>
    </joint>
    <actuator name="motor10">
      <hardwareInterface>hardware_interface/EffortJointInterface</hardwareInterface>
      <mechanicalReduction>1</mechanicalReduction>
    </actuator>
  </transmission>

</robot>