<?xml version="1.0"?>
<robot name="slider" xmlns:xacro="http://www.ros.org/wiki/xacro">

<gazebo>
  <plugin name="gazebo_ros_control" filename="libgazebo_ros_control.so">
    <robotNamespace>rotateSLIDER_Gazebo</robotNamespace>
    <legacyModeNS>true</legacyModeNS>
  </plugin>
</gazebo>

<!-- When the joint is near the soft limits, the possible velocities are bounded to keep the 
     position from crossing the soft limits. -->

<!--xacro for some constant -->
<xacro:property name="pelvis_height" value="0.8" />
<xacro:property name="right_offset"  value="-0.1" />
<xacro:property name="left_offset"   value="0.1" />
<xacro:property name="ground_friction"   value="0.75"/>
<xacro:property name="stiffness_kp"   value="1.0e+5" />
<xacro:property name="stiffness_kd"   value="1.0e+3" />

<selfCollide>false</selfCollide>

<!--MAKE THE pelvis FIXED in the air -->
  <link name="world"/>

  <joint name="base_joint" type="floating">
    <origin rpy="0 0 0" xyz="0 0 ${pelvis_height}"/>
    <parent link="world"/>
    <child link="pelvis"/>
  </joint>

  <link name="pelvis">
    <visual>
      <geometry>
        <box size = "0.26 0.16 0.18"/>
      </geometry>
      <origin rpy="0 0 0" xyz="0 0 0"/>
    </visual>
<!--     <collision>
      <geometry>
        <box size = "0.26 0.334 0.18"/>
      </geometry>
      <origin rpy="0 0 0" xyz="0.06 0 0"/>
    </collision> -->
    <inertial>
      <mass value="8.5"/>
      <origin rpy="0 0 0" xyz="0.0 0 0"/>
      <inertia ixx="0.0275" ixy="0" ixz="0" iyy="0.0708" iyz="0" izz="0.0524"/>
    </inertial>
  </link>

  <link name="torsoCasing">
    <visual>
      <geometry>
        <mesh filename="package://time_slider_gazebo/meshes/TorsoCasing_noDome.STL"/>
      </geometry>
      <origin rpy="0 0 0" xyz="0 0 0"/>
    </visual> 
<!--     <collision>
      <geometry>
        <mesh filename="package://time_slider_gazebo/meshes/TorsoCasing_noDome.STL"/>
      </geometry>
      <origin rpy="0 0 0" xyz="0 0 0"/>
    </collision> -->
<!--     <inertial>
      <mass value="0"/>
      <origin rpy="0 0 0" xyz="0 0 0"/>
      <inertia ixx="0.00137215" ixy="0" ixz="0" iyy="0.00132175" iyz="0" izz="0.0013696"/>
    </inertial>  -->
  </link>

 <joint name="torsoCasJoint" type="fixed">
    <origin rpy="1.5707 0 1.5707" xyz="-0.26 -0.30 -0.13"/>
    <parent link="pelvis"/>
    <child link="torsoCasing"/>
  </joint>


  <joint name="right_hip_roll" type="revolute">
    <axis xyz="1 0 0"/>
    <limit effort="700.0" lower="-0.7853" upper="0.7853" velocity="3"/>
    <safety_controller k_velocity="300" k_position="15000" soft_lower_limit="-0.6853" soft_upper_limit="0.6853" />
    <origin rpy="0 0 0" xyz="0 ${right_offset} 0"/>
    <parent link="pelvis"/>
    <child link="right_base_roll"/>
    <dynamics damping="0.7"/>
  </joint>

  <link name="right_base_roll">
    <visual>  
      <geometry>
        <cylinder radius="0.04" length="0.212"/>
      </geometry>
      <origin rpy="0 1.57 0" xyz="0 0 0"/>
    </visual>
<!--     <collision>
      <geometry>
        <cylinder radius="0.01" length="0.01"/>
      </geometry>
      <origin rpy="0 0 0" xyz="0 0 0"/>
    </collision> -->
    <inertial>
      <mass value="1"/>
      <origin rpy="0 1.57 0" xyz="0 0 0"/>
      <inertia ixx="0.0041" ixy="0.0" ixz="0.0" iyy="0.0041" iyz="0.0" izz="0.0008"/>
    </inertial>
  </link>

  <joint name="right_hip_pitch" type="revolute">
    <axis xyz="0 1 0"/>
    <limit effort="300.0" lower="-0.7853" upper="0.7853" velocity="999"/>
    <safety_controller k_velocity="300" k_position="30000" soft_lower_limit="-0.6853" soft_upper_limit="0.6853" />
    <origin rpy="0 0 0" xyz="0 0 0"/>
    <parent link="right_base_roll"/>
    <child link="right_base_pitch"/>
    <dynamics damping="0.7"/>
  </joint>

  <link name="right_base_pitch">
    <visual>	
      <geometry>
        <cylinder radius="0.04" length="0.212"/>
      </geometry>
      <origin rpy="1.57 0 0" xyz="0 0 0"/>
    </visual>
<!--     <collision>
      <geometry>
        <cylinder radius="0.04" length="0.17"/>
      </geometry>
      <origin rpy="1.57 0 0" xyz="0 0 0"/>
    </collision> -->
    <inertial>
      <mass value="0.003"/>
      <origin rpy="1.57 0 0" xyz="0 0 0"/>
      <inertia ixx="0.00001244" ixy="0.0" ixz="0.0" iyy="0.00001244" iyz="0.0" izz="0.00000240"/>
    </inertial>
  </link>

  <joint name="right_hip_slide" type="prismatic">
    <axis xyz="0 0 -1"/>
    <limit effort="600.0" lower="-1.2" upper="1.2" velocity="4"/>
    <safety_controller k_velocity="300" k_position="6000" soft_lower_limit="0.0" soft_upper_limit="1.1" />
    <origin rpy="0 0 0" xyz="0 -0.05 0"/>
    <parent link="right_base_pitch"/>
    <child link="right_slide_leg_link"/>
    <dynamics damping="0.7"/>
  </joint>


  <link name="right_slide_leg_link">
<!--     <visual>  
      <geometry>
        <cylinder radius="0.001" length="0.001"/>
      </geometry>
      <origin rpy="0 0 0" xyz="0 0 0"/>
    </visual>
    <inertial>
      <mass value="0.000001"/>
      <origin rpy="0 0 0" xyz="0 0 0"/>
      <inertia ixx="0.0001" ixy="0.0" ixz="0.0" iyy="0.000001" iyz="0.0" izz="0.0001"/>
    </inertial> -->
  </link>


  <joint name="right_slide_leg_link_joint" type="fixed">
    <origin rpy="0 0 0" xyz="0 0 -0.18"/>
    <parent link="right_slide_leg_link"/>
    <child link="right_leg"/>
  </joint>

  <link name="right_leg">
    <visual>
      <geometry>
        <cylinder radius="0.021" length="1.2"/>
      </geometry>
      <origin rpy="0 0 0" xyz="0 0 0"/>
    </visual>
    <!-- <collision>
      <geometry>
        <cylinder radius="0.021" length="1.2"/>
      </geometry>
      <origin rpy="0 0 0" xyz="0 0 0"/>
    </collision> -->
    <inertial>
      <mass value="1.5"/>
      <origin rpy="0 0 0" xyz="0 0 0"/>
      <inertia ixx="0.1802" ixy="0.0" ixz="0.0" iyy="0.1802" iyz="0" izz="0.0003"/>
    </inertial>
  </link>

  <link name="rightSlidingBox">
    <!-- <visual>
      <geometry>
        <mesh filename="package://time_slider_gazebo/meshes/RightSlidingBoxDefeature.STL"/>
      </geometry>
      <origin rpy="0 0 0" xyz="0 0 0"/>
    </visual> -->
<!--     <collision>
      <geometry>
        <mesh filename="package://time_slider_gazebo/meshes/RightSlidingBoxDefeature.STL"/>
      </geometry>
      <origin rpy="0 0 0" xyz="0 0 0"/>
    </collision> -->
<!--     <inertial>
      <mass value="0"/>
      <origin rpy="0 0 0" xyz="0 0 0"/>
      <inertia ixx="0.00137215" ixy="0" ixz="0" iyy="0.00132175" iyz="0" izz="0.0013696"/>
    </inertial>  -->
  </link>

  <joint name="rightSlidingBoxJoint" type="fixed">
    <origin rpy="0 0 1.57" xyz="0.33 -0.286 -0.4"/>
    <parent link="right_base_pitch"/>
    <child link="rightSlidingBox"/>
  </joint>


<joint name="rightLegTopFootJoint" type="fixed">
  <origin rpy="0 0 0" xyz="0 0 0.6"/>
  <parent link="right_leg"/>
  <child link="rightTopFoot"/>
</joint>

<link name="rightTopFoot">
  <visual>
    <geometry>
      <sphere radius = "0.02"/>
    </geometry>
    <origin rpy="0 0 0" xyz="0 0 0.0"/>
  </visual>
  <collision>
    <geometry>
      <sphere radius = "0.02"/>
    </geometry>
    <origin rpy="0 0 0" xyz="0.0 0 0.0"/>
    <!-- <surface>
      <friction>
        <ode>
          <mu>100</mu>
          <mu2>10000</mu2>
        </ode>
      </friction>
    </surface> -->
  </collision> 
  <inertial>
    <mass value="0.005"/>
    <origin rpy="0 0 0" xyz="0.0 0 0.0"/>
    <inertia ixx="0.0016" ixy="0" ixz="0" iyy="0.0016" iyz="0" izz="0.0016"/>
  </inertial>
</link>

<joint name="rightLegBottomFootJoint" type="fixed">
  <origin rpy="0 0 0" xyz="0 0 -0.6"/>
  <parent link="right_leg"/>
  <child link="rightBottomFoot"/>
</joint>

<link name="rightBottomFoot">
  <visual>
    <geometry>
      <sphere radius = "0.02"/>
    </geometry>
    <origin rpy="0 0 0" xyz="0 0 0.0"/>
  </visual>
  <collision>
    <geometry>
      <sphere radius = "0.02"/>
    </geometry>
    <surface>
      <friction>
        <ode>
          <mu>${ground_friction}</mu>
          <mu2>${ground_friction}</mu2>
        </ode>
      </friction>
    </surface>
    <origin rpy="0 0 0" xyz="0.0 0 0.0"/>
  </collision> 
  <inertial>
    <mass value="0.005"/>
    <origin rpy="0 0 0" xyz="0.0 0 0.0"/>
    <inertia ixx="0.0016" ixy="0" ixz="0" iyy="0.0016" iyz="0" izz="0.0016"/>
  </inertial>
</link>


<!-- left part -->
  <link name="left_base_roll">
    <visual>  
      <geometry>
        <cylinder radius="0.04" length="0.212"/>
      </geometry>
      <origin rpy="0 1.57 0" xyz="0 0 0"/>
    </visual>
<!--     <collision>
      <geometry>
        <cylinder radius="0.01" length="0.01"/>
      </geometry>
      <origin rpy="0 0 0" xyz="0 0 0"/>
    </collision> -->
    <inertial>
      <mass value="1"/>
      <origin rpy="0 1.57 0" xyz="0 0 0"/>
      <inertia ixx="0.0041" ixy="0.0" ixz="0.0" iyy="0.0041" iyz="0.0" izz="0.0008"/>
    </inertial>
  </link>

  <joint name="left_hip_roll" type="revolute">
    <axis xyz="1 0 0"/>
    <limit effort="700.0" lower="-0.7853" upper="0.7853" velocity="3"/>
    <safety_controller k_velocity="300" k_position="25000" soft_lower_limit="-0.6853" soft_upper_limit="0.6853"/>
    <origin rpy="0 0 0" xyz="0 ${left_offset} 0"/>
    <parent link="pelvis"/>
    <child link="left_base_roll"/>
    <dynamics damping="0.7"/>
  </joint>

  <!-- <link name="leftHipRollRender">
    <visual>
      <geometry>
        <mesh filename="package://time_slider_gazebo/meshes/HipRollBox.STL"/>
      </geometry>
      <origin rpy="0 0 0" xyz="0 0 0"/>
    </visual> -->
<!--     <collision>
      <geometry>
        <mesh filename="package://time_slider_gazebo/meshes/HipRollBox.STL"/>
      </geometry>
      <origin rpy="0 0 0" xyz="0 0 0"/>
    </collision> -->
<!--     <inertial>
      <mass value="0"/>
      <origin rpy="0 0 0" xyz="0 0 0"/>
       <inertia ixx="0.17215" ixy="0" ixz="0" iyy="0.12175" iyz="0" izz="0.1696"/>  originally
      <inertia ixx="0.00137215" ixy="0" ixz="0" iyy="0.00132175" iyz="0" izz="0.0013696"/>
    </inertial>  -->
  <!-- </link> -->

  <!-- <joint name="leftHipRollRenderJoint" type="fixed">
    <origin rpy="1.57 0 0" xyz="-0.20 0.08 -0.09"/>
    <parent link="left_base_roll"/>
    <child link="leftHipRollRender"/>
  </joint> -->

  <link name="left_base_pitch">
    <visual>	
      <geometry>
        <cylinder radius="0.04" length="0.212"/>
      </geometry>
      <material name="white"/>
      <origin rpy="1.57 0 0" xyz="0 0 0"/>
    </visual>
<!--     <collision>
      <geometry>
        <cylinder radius="0.04" length="0.17"/>
      </geometry>
      <origin rpy="1.57 0 0" xyz="0 0 0"/>
    </collision> -->
    <inertial>
      <mass value="0.003"/>
      <origin rpy="1.57 0 0" xyz="0 0 0"/>
      <inertia ixx="0.00001244" ixy="0.0" ixz="0.0" iyy="0.00001244" iyz="0.0" izz="0.00000240"/>
    </inertial>
  </link>

  <joint name="left_hip_pitch" type="revolute">
    <axis xyz="0 1 0"/>
    <limit effort="300.0" lower="-0.7853" upper="0.7853" velocity="999"/>
    <safety_controller k_velocity="300" k_position="30000" soft_lower_limit="-0.6853" soft_upper_limit="0.6853"/>
    <origin rpy="0 0 0" xyz="0 0 0"/>
    <parent link="left_base_roll"/>
    <child link="left_base_pitch"/>
    <dynamics damping="0.7"/>
  </joint>


  <joint name="left_hip_slide" type="prismatic">
    <axis xyz="0 0 -1"/>
    <limit effort="600.0" lower="-1.2" upper="1.2" velocity="4"/>
    <safety_controller k_velocity="300" k_position="6000" soft_lower_limit="0.0" soft_upper_limit="1.1" />
    <origin rpy="0 0 0" xyz="0 0.05 0"/>
    <parent link="left_base_pitch"/>
    <child link="left_slide_leg_link"/>
    <dynamics damping="0.7"/>
  </joint>

  <link name="left_slide_leg_link">
<!--     <visual>  
      <geometry>
        <cylinder radius="0.001" length="0.001"/>
      </geometry>
      <origin rpy="0 0 0" xyz="0 0 0"/>
    </visual>
    <inertial>
      <mass value="0.000001"/>
      <origin rpy="0 0 0" xyz="0 0 0"/>
      <inertia ixx="0.0001" ixy="0.0" ixz="0.0" iyy="0.000001" iyz="0.0" izz="0.0001"/>
    </inertial> -->
  </link>


  <joint name="left_slide_leg_link_joint" type="fixed">
    <origin rpy="0 0 0" xyz="0 0 -0.18"/>
    <parent link="left_slide_leg_link"/>
    <child link="left_leg"/>
  </joint>

  <link name="left_leg">
    <visual>
      <geometry>
        <cylinder radius="0.021" length="1.2"/>
      </geometry>
      <origin rpy="0 0 0" xyz="0 0 0"/>
      <material name="black"/>
    </visual>
    <!-- <collision>
      <geometry>
        <cylinder radius="0.021" length="1.2"/>
      </geometry>
      <origin rpy="0 0 0" xyz="0 0 0"/>
    </collision> -->
    <inertial>
      <mass value="1.5"/>
      <origin rpy="0 0 0" xyz="0 0 0"/>
      <inertia ixx="0.1802" ixy="0.0" ixz="0.0" iyy="0.1802" iyz="0" izz="0.0003"/>
    </inertial>
  </link>

 
  <link name="leftSlidingBox">
    <!-- <visual>
      <geometry>
        <mesh filename="package://time_slider_gazebo/meshes/LeftSlidingBoxDefeature.STL"/>
      </geometry>
      <origin rpy="0 0 0" xyz="0 0 0"/>
    </visual> -->
<!--     <collision>
      <geometry>
        <mesh filename="package://time_slider_gazebo/meshes/LeftSlidingBoxDefeature.STL"/>
      </geometry>
      <origin rpy="0 0 0" xyz="0 0 0"/>
    </collision> -->
<!--     <inertial>
      <mass value="0"/>
      <origin rpy="0 0 0" xyz="0 0 0"/>
      <inertia ixx="0.0137215" ixy="0" ixz="0" iyy="0.0132175" iyz="0" izz="0.013696"/>
    </inertial>  -->
  </link>

  <joint name="leftSlidingBoxJoint" type="fixed">
    <origin rpy="0 0 1.57" xyz="0.33 0.056 -0.4"/>
    <parent link="left_base_pitch"/>
    <child link="leftSlidingBox"/>
  </joint>

  <joint name="leftLegTopFootJoint" type="fixed">
  <origin rpy="0 0 0" xyz="0 0 0.6"/>
  <parent link="left_leg"/>
  <child link="leftTopFoot"/>
</joint>

<link name="leftTopFoot">
  <visual>
    <geometry>
      <sphere radius = "0.02"/>
    </geometry>
    <origin rpy="0 0 0" xyz="0 0 0.0"/>
  </visual>
  <collision>
    <geometry>
      <sphere radius = "0.02"/>
    </geometry>
    <origin rpy="0 0 0" xyz="0.0 0 0.0"/>
  </collision> 
  <inertial>
    <mass value="0.005"/>
    <origin rpy="0 0 0" xyz="0.0 0 0.0"/>
    <inertia ixx="0.0016" ixy="0" ixz="0" iyy="0.0016" iyz="0" izz="0.0016"/>
  </inertial>
</link>

<joint name="leftLegBottomFootJoint" type="fixed">
  <origin rpy="0 0 0" xyz="0 0 -0.6"/>
  <parent link="left_leg"/>
  <child link="leftBottomFoot"/>
</joint>

<link name="leftBottomFoot">
  <visual>
    <geometry>
      <sphere radius = "0.02"/>
    </geometry>
    <origin rpy="0 0 0" xyz="0 0 0.0"/>
  </visual>
  <collision>
    <geometry>
      <sphere radius = "0.02"/>
    </geometry>
    <surface>
      <friction>
        <ode>
          <mu>${ground_friction}</mu>
          <mu2>${ground_friction}</mu2>
        </ode>
      </friction>
    </surface>
    <origin rpy="0 0 0" xyz="0.0 0 0.0"/>
  </collision> 
  <inertial>
    <mass value="0.005"/>
    <origin rpy="0 0 0" xyz="0.0 0 0.0"/>
    <inertia ixx="0.0016" ixy="0" ixz="0" iyy="0.0016" iyz="0" izz="0.0016"/>
  </inertial>
</link>

<!-- assign colors to different parts of SLIDER -->
  <gazebo reference="pelvis">
    <!-- <material>Gazebo/Yellow</material> -->
    <material>Gazebo/White</material>
  </gazebo>

  <gazebo reference="torsoCasing">
    <!-- <material>Gazebo/Orange</material> -->
    <!-- <material>Gazebo/Red</material> -->
    <material>Gazebo/White</material>
  </gazebo>

  <gazebo reference="left_base_pitch">
    <!-- <material>Gazebo/Blue</material> -->
    <material>Gazebo/Purple</material>
  </gazebo>
  <gazebo reference="right_base_pitch">
    <!-- <material>Gazebo/Red</material> -->
    <material>Gazebo/Purple</material>
  </gazebo>

  <gazebo reference="left_base_roll">
    <!-- <material>Gazebo/Blue</material> -->
    <material>Gazebo/Red</material>
  </gazebo>
  <gazebo reference="right_base_roll">
    <!-- <material>Gazebo/Red</material> -->
    <material>Gazebo/Red</material>
  </gazebo>

  <gazebo reference="right_leg">
    <!-- <material>Gazebo/Red</material> -->
    <material>Gazebo/White</material>
  </gazebo>

  <gazebo reference="left_leg">
    <material>Gazebo/White</material>
    <!-- <material>Gazebo/Blue</material> -->
  </gazebo>

  <!-- Transmissions used for ros_control -->
  <transmission name="tran1">
    <type>transmission_interface/SimpleTransmission</type>
    <joint name="left_hip_pitch">
      <hardwareInterface>hardware_interface/EffortJointInterface</hardwareInterface>
    </joint>
    <actuator name="motor1">
      <hardwareInterface>hardware_interface/EffortJointInterface</hardwareInterface>
      <mechanicalReduction>1</mechanicalReduction>
    </actuator>
  </transmission>

  <transmission name="tran2">
    <type>transmission_interface/SimpleTransmission</type>
    <joint name="left_hip_roll">
      <hardwareInterface>hardware_interface/EffortJointInterface</hardwareInterface>
    </joint>
    <actuator name="motor2">
      <hardwareInterface>hardware_interface/EffortJointInterface</hardwareInterface>
      <mechanicalReduction>1</mechanicalReduction>
    </actuator>
  </transmission>

  <transmission name="tran3">
    <type>transmission_interface/SimpleTransmission</type>
    <joint name="left_hip_slide">
      <hardwareInterface>hardware_interface/EffortJointInterface</hardwareInterface>
    </joint>
    <actuator name="motor3">
      <hardwareInterface>hardware_interface/EffortJointInterface</hardwareInterface>
      <mechanicalReduction>1</mechanicalReduction>
    </actuator>
  </transmission>

  <transmission name="tran4">
    <type>transmission_interface/SimpleTransmission</type>
    <joint name="right_hip_pitch">
      <hardwareInterface>hardware_interface/EffortJointInterface</hardwareInterface>
    </joint>
    <actuator name="motor4">
      <hardwareInterface>hardware_interface/EffortJointInterface</hardwareInterface>
      <mechanicalReduction>1</mechanicalReduction>
    </actuator>
  </transmission>

  <transmission name="tran5">
    <type>transmission_interface/SimpleTransmission</type>
    <joint name="right_hip_roll">
      <hardwareInterface>hardware_interface/EffortJointInterface</hardwareInterface>
    </joint>
    <actuator name="motor5">
      <hardwareInterface>hardware_interface/EffortJointInterface</hardwareInterface>
      <mechanicalReduction>1</mechanicalReduction>
    </actuator>
  </transmission>

  <transmission name="tran6">
    <type>transmission_interface/SimpleTransmission</type>
    <joint name="right_hip_slide">
      <hardwareInterface>hardware_interface/EffortJointInterface</hardwareInterface>
    </joint>
    <actuator name="motor6">
      <hardwareInterface>hardware_interface/EffortJointInterface</hardwareInterface>
      <mechanicalReduction>1</mechanicalReduction>
    </actuator>
  </transmission>
</robot>
